2019-05-01 14:41:22,691 ERROR: Exception on /courses/create [POST] [in c:\python36\lib\site-packages\flask\app.py:1560]
Traceback (most recent call last):
  File "c:\python36\lib\site-packages\flask\app.py", line 1982, in wsgi_app
    response = self.full_dispatch_request()
  File "c:\python36\lib\site-packages\flask\app.py", line 1614, in full_dispatch_request
    rv = self.handle_user_exception(e)
  File "c:\python36\lib\site-packages\flask\app.py", line 1517, in handle_user_exception
    reraise(exc_type, exc_value, tb)
  File "c:\python36\lib\site-packages\flask\_compat.py", line 33, in reraise
    raise value
  File "c:\python36\lib\site-packages\flask\app.py", line 1612, in full_dispatch_request
    rv = self.dispatch_request()
  File "c:\python36\lib\site-packages\flask\app.py", line 1598, in dispatch_request
    return self.view_functions[rule.endpoint](**req.view_args)
  File "c:\python36\lib\site-packages\flask_login\utils.py", line 261, in decorated_view
    return func(*args, **kwargs)
  File "C:\Users\Adam\desktop\City Tech Proj\app\routes.py", line 229, in createCourseForm
    newCourse = Courses(name = name, code= code, credits = int(credits), dept = dept)
ValueError: invalid literal for int() with base 10: ''
2019-05-01 14:42:35,933 ERROR: Exception on /courses/create [POST] [in c:\python36\lib\site-packages\flask\app.py:1560]
Traceback (most recent call last):
  File "c:\python36\lib\site-packages\flask\app.py", line 1982, in wsgi_app
    response = self.full_dispatch_request()
  File "c:\python36\lib\site-packages\flask\app.py", line 1614, in full_dispatch_request
    rv = self.handle_user_exception(e)
  File "c:\python36\lib\site-packages\flask\app.py", line 1517, in handle_user_exception
    reraise(exc_type, exc_value, tb)
  File "c:\python36\lib\site-packages\flask\_compat.py", line 33, in reraise
    raise value
  File "c:\python36\lib\site-packages\flask\app.py", line 1612, in full_dispatch_request
    rv = self.dispatch_request()
  File "c:\python36\lib\site-packages\flask\app.py", line 1598, in dispatch_request
    return self.view_functions[rule.endpoint](**req.view_args)
  File "c:\python36\lib\site-packages\flask_login\utils.py", line 261, in decorated_view
    return func(*args, **kwargs)
  File "C:\Users\Adam\desktop\City Tech Proj\app\routes.py", line 229, in createCourseForm
    newCourse = Courses(name = name, code= code, credits = int(credits), dept = dept)
ValueError: invalid literal for int() with base 10: ''
2019-05-01 14:43:59,409 INFO: CreditTracker startup [in C:\Users\Adam\desktop\City Tech Proj\app\__init__.py:37]
2019-05-01 14:51:32,424 INFO: CreditTracker startup [in C:\Users\Adam\desktop\City Tech Proj\app\__init__.py:37]
2019-05-01 14:52:35,239 INFO: CreditTracker startup [in C:\Users\Adam\desktop\City Tech Proj\app\__init__.py:37]
2019-05-01 14:53:19,342 INFO: CreditTracker startup [in C:\Users\Adam\desktop\City Tech Proj\app\__init__.py:37]
2019-05-01 14:56:58,222 INFO: CreditTracker startup [in C:\Users\Adam\desktop\City Tech Proj\app\__init__.py:37]
2019-05-01 14:58:22,502 INFO: CreditTracker startup [in C:\Users\Adam\desktop\City Tech Proj\app\__init__.py:37]
2019-05-01 17:22:07,461 INFO: CreditTracker startup [in C:\Users\Adam\desktop\City Tech Proj\app\__init__.py:37]
2019-05-01 17:23:55,296 INFO: CreditTracker startup [in C:\Users\Adam\desktop\City Tech Proj\app\__init__.py:37]
2019-05-01 17:50:30,524 ERROR: Exception on /programs/create [POST] [in c:\python36\lib\site-packages\flask\app.py:1560]
Traceback (most recent call last):
  File "c:\python36\lib\site-packages\flask\app.py", line 1982, in wsgi_app
    response = self.full_dispatch_request()
  File "c:\python36\lib\site-packages\flask\app.py", line 1614, in full_dispatch_request
    rv = self.handle_user_exception(e)
  File "c:\python36\lib\site-packages\flask\app.py", line 1517, in handle_user_exception
    reraise(exc_type, exc_value, tb)
  File "c:\python36\lib\site-packages\flask\_compat.py", line 33, in reraise
    raise value
  File "c:\python36\lib\site-packages\flask\app.py", line 1612, in full_dispatch_request
    rv = self.dispatch_request()
  File "c:\python36\lib\site-packages\flask\app.py", line 1598, in dispatch_request
    return self.view_functions[rule.endpoint](**req.view_args)
  File "c:\python36\lib\site-packages\flask_login\utils.py", line 261, in decorated_view
    return func(*args, **kwargs)
  File "C:\Users\Adam\desktop\City Tech Proj\app\routes.py", line 164, in createProgramForm
    newProgram = Programs(name = name, code= code, degree = degree)
  File "<string>", line 4, in __init__
  File "c:\python36\lib\site-packages\sqlalchemy\orm\state.py", line 417, in _initialize_instance
    manager.dispatch.init_failure(self, args, kwargs)
  File "c:\python36\lib\site-packages\sqlalchemy\util\langhelpers.py", line 66, in __exit__
    compat.reraise(exc_type, exc_value, exc_tb)
  File "c:\python36\lib\site-packages\sqlalchemy\util\compat.py", line 187, in reraise
    raise value
  File "c:\python36\lib\site-packages\sqlalchemy\orm\state.py", line 414, in _initialize_instance
    return manager.original_init(*mixed[1:], **kwargs)
  File "c:\python36\lib\site-packages\sqlalchemy\ext\declarative\base.py", line 699, in _declarative_constructor
    (k, cls_.__name__))
TypeError: 'code' is an invalid keyword argument for Programs
2019-05-01 17:50:49,664 ERROR: Exception on /programs/create [POST] [in c:\python36\lib\site-packages\flask\app.py:1560]
Traceback (most recent call last):
  File "c:\python36\lib\site-packages\flask\app.py", line 1982, in wsgi_app
    response = self.full_dispatch_request()
  File "c:\python36\lib\site-packages\flask\app.py", line 1614, in full_dispatch_request
    rv = self.handle_user_exception(e)
  File "c:\python36\lib\site-packages\flask\app.py", line 1517, in handle_user_exception
    reraise(exc_type, exc_value, tb)
  File "c:\python36\lib\site-packages\flask\_compat.py", line 33, in reraise
    raise value
  File "c:\python36\lib\site-packages\flask\app.py", line 1612, in full_dispatch_request
    rv = self.dispatch_request()
  File "c:\python36\lib\site-packages\flask\app.py", line 1598, in dispatch_request
    return self.view_functions[rule.endpoint](**req.view_args)
  File "c:\python36\lib\site-packages\flask_login\utils.py", line 261, in decorated_view
    return func(*args, **kwargs)
  File "C:\Users\Adam\desktop\City Tech Proj\app\routes.py", line 164, in createProgramForm
    newProgram = Programs(name = name, code= code, degree = degree)
  File "<string>", line 4, in __init__
  File "c:\python36\lib\site-packages\sqlalchemy\orm\state.py", line 417, in _initialize_instance
    manager.dispatch.init_failure(self, args, kwargs)
  File "c:\python36\lib\site-packages\sqlalchemy\util\langhelpers.py", line 66, in __exit__
    compat.reraise(exc_type, exc_value, exc_tb)
  File "c:\python36\lib\site-packages\sqlalchemy\util\compat.py", line 187, in reraise
    raise value
  File "c:\python36\lib\site-packages\sqlalchemy\orm\state.py", line 414, in _initialize_instance
    return manager.original_init(*mixed[1:], **kwargs)
  File "c:\python36\lib\site-packages\sqlalchemy\ext\declarative\base.py", line 699, in _declarative_constructor
    (k, cls_.__name__))
TypeError: 'code' is an invalid keyword argument for Programs
2019-05-05 21:13:25,525 INFO: CreditTracker startup [in C:\Users\Adam\desktop\City Tech Proj\app\__init__.py:37]
2019-05-06 14:43:52,040 INFO: CreditTracker startup [in C:\Users\Adam\desktop\City Tech Proj\app\__init__.py:37]
2019-05-06 14:47:57,669 ERROR: Exception on /programs/create [POST] [in c:\python36\lib\site-packages\flask\app.py:1560]
Traceback (most recent call last):
  File "c:\python36\lib\site-packages\flask\app.py", line 1982, in wsgi_app
    response = self.full_dispatch_request()
  File "c:\python36\lib\site-packages\flask\app.py", line 1614, in full_dispatch_request
    rv = self.handle_user_exception(e)
  File "c:\python36\lib\site-packages\flask\app.py", line 1517, in handle_user_exception
    reraise(exc_type, exc_value, tb)
  File "c:\python36\lib\site-packages\flask\_compat.py", line 33, in reraise
    raise value
  File "c:\python36\lib\site-packages\flask\app.py", line 1612, in full_dispatch_request
    rv = self.dispatch_request()
  File "c:\python36\lib\site-packages\flask\app.py", line 1598, in dispatch_request
    return self.view_functions[rule.endpoint](**req.view_args)
  File "c:\python36\lib\site-packages\flask_login\utils.py", line 261, in decorated_view
    return func(*args, **kwargs)
  File "C:\Users\Adam\desktop\City Tech Proj\app\routes.py", line 164, in createProgramForm
    newProgram = Programs(name = name, code= code, degree = degree)
  File "<string>", line 4, in __init__
  File "c:\python36\lib\site-packages\sqlalchemy\orm\state.py", line 417, in _initialize_instance
    manager.dispatch.init_failure(self, args, kwargs)
  File "c:\python36\lib\site-packages\sqlalchemy\util\langhelpers.py", line 66, in __exit__
    compat.reraise(exc_type, exc_value, exc_tb)
  File "c:\python36\lib\site-packages\sqlalchemy\util\compat.py", line 187, in reraise
    raise value
  File "c:\python36\lib\site-packages\sqlalchemy\orm\state.py", line 414, in _initialize_instance
    return manager.original_init(*mixed[1:], **kwargs)
  File "c:\python36\lib\site-packages\sqlalchemy\ext\declarative\base.py", line 699, in _declarative_constructor
    (k, cls_.__name__))
TypeError: 'code' is an invalid keyword argument for Programs
2019-05-06 14:55:51,915 INFO: CreditTracker startup [in C:\Users\Adam\desktop\City Tech Proj\app\__init__.py:37]
