2019-06-30 20:25:17,846 INFO: CreditTracker startup [in C:\Users\Adam\desktop\City Tech Proj\app\__init__.py:37]
2019-06-30 20:25:28,789 ERROR: Exception on /depts/create [GET] [in c:\python36\lib\site-packages\flask\app.py:1560]
Traceback (most recent call last):
  File "c:\python36\lib\site-packages\flask\app.py", line 1982, in wsgi_app
    response = self.full_dispatch_request()
  File "c:\python36\lib\site-packages\flask\app.py", line 1614, in full_dispatch_request
    rv = self.handle_user_exception(e)
  File "c:\python36\lib\site-packages\flask\app.py", line 1517, in handle_user_exception
    reraise(exc_type, exc_value, tb)
  File "c:\python36\lib\site-packages\flask\_compat.py", line 33, in reraise
    raise value
  File "c:\python36\lib\site-packages\flask\app.py", line 1612, in full_dispatch_request
    rv = self.dispatch_request()
  File "c:\python36\lib\site-packages\flask\app.py", line 1598, in dispatch_request
    return self.view_functions[rule.endpoint](**req.view_args)
  File "c:\python36\lib\site-packages\flask_user\decorators.py", line 129, in decorator
    user_manager = current_app.user_manager
  File "c:\python36\lib\site-packages\werkzeug\local.py", line 347, in __getattr__
    return getattr(self._get_current_object(), name)
AttributeError: 'Flask' object has no attribute 'user_manager'
2019-06-30 20:34:34,585 INFO: CreditTracker startup [in C:\Users\Adam\desktop\City Tech Proj\app\__init__.py:37]
2019-06-30 20:35:05,856 ERROR: Exception on /depts/create [GET] [in c:\python36\lib\site-packages\flask\app.py:1560]
Traceback (most recent call last):
  File "c:\python36\lib\site-packages\flask\app.py", line 1982, in wsgi_app
    response = self.full_dispatch_request()
  File "c:\python36\lib\site-packages\flask\app.py", line 1614, in full_dispatch_request
    rv = self.handle_user_exception(e)
  File "c:\python36\lib\site-packages\flask\app.py", line 1517, in handle_user_exception
    reraise(exc_type, exc_value, tb)
  File "c:\python36\lib\site-packages\flask\_compat.py", line 33, in reraise
    raise value
  File "c:\python36\lib\site-packages\flask\app.py", line 1612, in full_dispatch_request
    rv = self.dispatch_request()
  File "c:\python36\lib\site-packages\flask\app.py", line 1598, in dispatch_request
    return self.view_functions[rule.endpoint](**req.view_args)
  File "c:\python36\lib\site-packages\flask_user\decorators.py", line 129, in decorator
    user_manager = current_app.user_manager
  File "c:\python36\lib\site-packages\werkzeug\local.py", line 347, in __getattr__
    return getattr(self._get_current_object(), name)
AttributeError: 'Flask' object has no attribute 'user_manager'
2019-06-30 20:52:26,079 INFO: CreditTracker startup [in C:\Users\Adam\desktop\City Tech Proj\app\__init__.py:37]
2019-06-30 21:06:50,450 INFO: CreditTracker startup [in C:\Users\Adam\desktop\City Tech Proj\app\__init__.py:40]
2019-06-30 21:07:28,853 INFO: CreditTracker startup [in C:\Users\Adam\desktop\City Tech Proj\app\__init__.py:40]
2019-06-30 21:07:57,529 INFO: CreditTracker startup [in C:\Users\Adam\desktop\City Tech Proj\app\__init__.py:40]
2019-06-30 21:09:13,746 INFO: CreditTracker startup [in C:\Users\Adam\desktop\City Tech Proj\app\__init__.py:44]
2019-06-30 21:09:54,842 INFO: CreditTracker startup [in C:\Users\Adam\desktop\City Tech Proj\app\__init__.py:40]
2019-06-30 21:12:14,487 INFO: CreditTracker startup [in C:\Users\Adam\desktop\City Tech Proj\app\__init__.py:40]
2019-06-30 21:21:33,024 INFO: CreditTracker startup [in C:\Users\Adam\desktop\City Tech Proj\app\__init__.py:40]
2019-06-30 21:25:01,581 INFO: CreditTracker startup [in C:\Users\Adam\desktop\City Tech Proj\app\__init__.py:40]
2019-06-30 21:25:02,547 ERROR: Exception on /depts/create [GET] [in c:\python36\lib\site-packages\flask\app.py:1560]
Traceback (most recent call last):
  File "c:\python36\lib\site-packages\flask\app.py", line 1982, in wsgi_app
    response = self.full_dispatch_request()
  File "c:\python36\lib\site-packages\flask\app.py", line 1614, in full_dispatch_request
    rv = self.handle_user_exception(e)
  File "c:\python36\lib\site-packages\flask\app.py", line 1517, in handle_user_exception
    reraise(exc_type, exc_value, tb)
  File "c:\python36\lib\site-packages\flask\_compat.py", line 33, in reraise
    raise value
  File "c:\python36\lib\site-packages\flask\app.py", line 1612, in full_dispatch_request
    rv = self.dispatch_request()
  File "c:\python36\lib\site-packages\flask\app.py", line 1598, in dispatch_request
    return self.view_functions[rule.endpoint](**req.view_args)
  File "C:\Users\Adam\desktop\City Tech Proj\app\routes.py", line 115, in createDeptForm
    print(current_user.name)
  File "c:\python36\lib\site-packages\werkzeug\local.py", line 347, in __getattr__
    return getattr(self._get_current_object(), name)
AttributeError: 'User' object has no attribute 'name'
2019-06-30 21:25:31,542 INFO: CreditTracker startup [in C:\Users\Adam\desktop\City Tech Proj\app\__init__.py:40]
2019-07-02 14:43:53,512 INFO: CreditTracker startup [in C:\Users\Adam\desktop\City Tech Proj\app\__init__.py:40]
2019-07-02 15:00:17,766 INFO: CreditTracker startup [in C:\Users\Adam\desktop\City Tech Proj\app\__init__.py:40]
2019-07-02 15:00:18,990 ERROR: Exception on / [GET] [in c:\python36\lib\site-packages\flask\app.py:1560]
Traceback (most recent call last):
  File "c:\python36\lib\site-packages\flask\app.py", line 1982, in wsgi_app
    response = self.full_dispatch_request()
  File "c:\python36\lib\site-packages\flask\app.py", line 1614, in full_dispatch_request
    rv = self.handle_user_exception(e)
  File "c:\python36\lib\site-packages\flask\app.py", line 1517, in handle_user_exception
    reraise(exc_type, exc_value, tb)
  File "c:\python36\lib\site-packages\flask\_compat.py", line 33, in reraise
    raise value
  File "c:\python36\lib\site-packages\flask\app.py", line 1612, in full_dispatch_request
    rv = self.dispatch_request()
  File "c:\python36\lib\site-packages\flask\app.py", line 1598, in dispatch_request
    return self.view_functions[rule.endpoint](**req.view_args)
  File "C:\Users\Adam\desktop\City Tech Proj\app\routes.py", line 18, in creditDashboard
    print({{current_user.name}})
  File "c:\python36\lib\site-packages\werkzeug\local.py", line 347, in __getattr__
    return getattr(self._get_current_object(), name)
AttributeError: 'AnonymousUserMixin' object has no attribute 'name'
2019-07-02 15:00:46,057 INFO: CreditTracker startup [in C:\Users\Adam\desktop\City Tech Proj\app\__init__.py:40]
2019-07-02 15:00:46,489 ERROR: Exception on / [GET] [in c:\python36\lib\site-packages\flask\app.py:1560]
Traceback (most recent call last):
  File "c:\python36\lib\site-packages\flask\app.py", line 1982, in wsgi_app
    response = self.full_dispatch_request()
  File "c:\python36\lib\site-packages\flask\app.py", line 1614, in full_dispatch_request
    rv = self.handle_user_exception(e)
  File "c:\python36\lib\site-packages\flask\app.py", line 1517, in handle_user_exception
    reraise(exc_type, exc_value, tb)
  File "c:\python36\lib\site-packages\flask\_compat.py", line 33, in reraise
    raise value
  File "c:\python36\lib\site-packages\flask\app.py", line 1612, in full_dispatch_request
    rv = self.dispatch_request()
  File "c:\python36\lib\site-packages\flask\app.py", line 1598, in dispatch_request
    return self.view_functions[rule.endpoint](**req.view_args)
  File "C:\Users\Adam\desktop\City Tech Proj\app\routes.py", line 18, in creditDashboard
    print(current_user.name)
  File "c:\python36\lib\site-packages\werkzeug\local.py", line 347, in __getattr__
    return getattr(self._get_current_object(), name)
AttributeError: 'AnonymousUserMixin' object has no attribute 'name'
2019-07-02 15:00:58,820 INFO: CreditTracker startup [in C:\Users\Adam\desktop\City Tech Proj\app\__init__.py:40]
2019-07-02 15:01:32,082 INFO: CreditTracker startup [in C:\Users\Adam\desktop\City Tech Proj\app\__init__.py:40]
2019-07-02 15:02:26,484 ERROR: Exception on /depts [GET] [in c:\python36\lib\site-packages\flask\app.py:1560]
Traceback (most recent call last):
  File "c:\python36\lib\site-packages\flask\app.py", line 1982, in wsgi_app
    response = self.full_dispatch_request()
  File "c:\python36\lib\site-packages\flask\app.py", line 1614, in full_dispatch_request
    rv = self.handle_user_exception(e)
  File "c:\python36\lib\site-packages\flask\app.py", line 1517, in handle_user_exception
    reraise(exc_type, exc_value, tb)
  File "c:\python36\lib\site-packages\flask\_compat.py", line 33, in reraise
    raise value
  File "c:\python36\lib\site-packages\flask\app.py", line 1612, in full_dispatch_request
    rv = self.dispatch_request()
  File "c:\python36\lib\site-packages\flask\app.py", line 1598, in dispatch_request
    return self.view_functions[rule.endpoint](**req.view_args)
  File "C:\Users\Adam\desktop\City Tech Proj\app\routes.py", line 100, in deptDashboard
    print(current_user.name)
  File "c:\python36\lib\site-packages\werkzeug\local.py", line 347, in __getattr__
    return getattr(self._get_current_object(), name)
AttributeError: 'User' object has no attribute 'name'
2019-07-02 15:02:39,449 INFO: CreditTracker startup [in C:\Users\Adam\desktop\City Tech Proj\app\__init__.py:40]
2019-07-02 15:03:47,807 INFO: CreditTracker startup [in C:\Users\Adam\desktop\City Tech Proj\app\__init__.py:40]
2019-07-02 15:05:29,399 INFO: CreditTracker startup [in C:\Users\Adam\desktop\City Tech Proj\app\__init__.py:40]
2019-07-02 15:05:58,939 INFO: CreditTracker startup [in C:\Users\Adam\desktop\City Tech Proj\app\__init__.py:40]
2019-07-02 15:07:39,717 INFO: CreditTracker startup [in C:\Users\Adam\desktop\City Tech Proj\app\__init__.py:40]
2019-07-02 20:01:22,069 INFO: CreditTracker startup [in C:\Users\Adam\desktop\City Tech Proj\app\__init__.py:40]
2019-07-02 20:08:05,922 INFO: CreditTracker startup [in C:\Users\Adam\desktop\City Tech Proj\app\__init__.py:40]
2019-07-02 20:08:26,250 INFO: CreditTracker startup [in C:\Users\Adam\desktop\City Tech Proj\app\__init__.py:40]
