2019-03-31 20:46:49,870 ERROR: Exception on /courses/edit/2 [POST] [in c:\python36\lib\site-packages\flask\app.py:1560]
Traceback (most recent call last):
  File "c:\python36\lib\site-packages\flask\app.py", line 1982, in wsgi_app
    response = self.full_dispatch_request()
  File "c:\python36\lib\site-packages\flask\app.py", line 1614, in full_dispatch_request
    rv = self.handle_user_exception(e)
  File "c:\python36\lib\site-packages\flask\app.py", line 1517, in handle_user_exception
    reraise(exc_type, exc_value, tb)
  File "c:\python36\lib\site-packages\flask\_compat.py", line 33, in reraise
    raise value
  File "c:\python36\lib\site-packages\flask\app.py", line 1612, in full_dispatch_request
    rv = self.dispatch_request()
  File "c:\python36\lib\site-packages\flask\app.py", line 1598, in dispatch_request
    return self.view_functions[rule.endpoint](**req.view_args)
  File "C:\Users\Adam\desktop\City Tech Proj\app\routes.py", line 297, in editCourseForm
    coreq_course = Courses.query.filter_by(id=coreq_course_id).one()
  File "c:\python36\lib\site-packages\sqlalchemy\orm\query.py", line 2843, in one
    raise orm_exc.NoResultFound("No row was found for one()")
sqlalchemy.orm.exc.NoResultFound: No row was found for one()
2019-03-31 20:49:39,115 INFO: CreditTracker startup [in C:\Users\Adam\desktop\City Tech Proj\app\__init__.py:37]
2019-03-31 20:49:57,694 ERROR: Exception on /courses/edit/2 [POST] [in c:\python36\lib\site-packages\flask\app.py:1560]
Traceback (most recent call last):
  File "c:\python36\lib\site-packages\flask\app.py", line 1982, in wsgi_app
    response = self.full_dispatch_request()
  File "c:\python36\lib\site-packages\flask\app.py", line 1614, in full_dispatch_request
    rv = self.handle_user_exception(e)
  File "c:\python36\lib\site-packages\flask\app.py", line 1517, in handle_user_exception
    reraise(exc_type, exc_value, tb)
  File "c:\python36\lib\site-packages\flask\_compat.py", line 33, in reraise
    raise value
  File "c:\python36\lib\site-packages\flask\app.py", line 1612, in full_dispatch_request
    rv = self.dispatch_request()
  File "c:\python36\lib\site-packages\flask\app.py", line 1598, in dispatch_request
    return self.view_functions[rule.endpoint](**req.view_args)
  File "C:\Users\Adam\desktop\City Tech Proj\app\routes.py", line 297, in editCourseForm
    coreq_course = Courses.query.filter_by(id=coreq_course_id).one()
  File "c:\python36\lib\site-packages\sqlalchemy\orm\query.py", line 2843, in one
    raise orm_exc.NoResultFound("No row was found for one()")
sqlalchemy.orm.exc.NoResultFound: No row was found for one()
2019-03-31 20:51:52,665 INFO: CreditTracker startup [in C:\Users\Adam\desktop\City Tech Proj\app\__init__.py:37]
2019-03-31 20:52:03,054 ERROR: Exception on /courses/edit/2 [POST] [in c:\python36\lib\site-packages\flask\app.py:1560]
Traceback (most recent call last):
  File "c:\python36\lib\site-packages\flask\app.py", line 1982, in wsgi_app
    response = self.full_dispatch_request()
  File "c:\python36\lib\site-packages\flask\app.py", line 1614, in full_dispatch_request
    rv = self.handle_user_exception(e)
  File "c:\python36\lib\site-packages\flask\app.py", line 1517, in handle_user_exception
    reraise(exc_type, exc_value, tb)
  File "c:\python36\lib\site-packages\flask\_compat.py", line 33, in reraise
    raise value
  File "c:\python36\lib\site-packages\flask\app.py", line 1612, in full_dispatch_request
    rv = self.dispatch_request()
  File "c:\python36\lib\site-packages\flask\app.py", line 1598, in dispatch_request
    return self.view_functions[rule.endpoint](**req.view_args)
  File "C:\Users\Adam\desktop\City Tech Proj\app\routes.py", line 280, in editCourseForm
    prereq_course = Courses.query.filter_by(id=prereq_course_id).one()
  File "c:\python36\lib\site-packages\sqlalchemy\orm\query.py", line 2843, in one
    raise orm_exc.NoResultFound("No row was found for one()")
sqlalchemy.orm.exc.NoResultFound: No row was found for one()
2019-03-31 20:52:50,883 INFO: CreditTracker startup [in C:\Users\Adam\desktop\City Tech Proj\app\__init__.py:37]
2019-03-31 20:53:24,438 ERROR: Exception on /courses/edit/2 [POST] [in c:\python36\lib\site-packages\flask\app.py:1560]
Traceback (most recent call last):
  File "c:\python36\lib\site-packages\flask\app.py", line 1982, in wsgi_app
    response = self.full_dispatch_request()
  File "c:\python36\lib\site-packages\flask\app.py", line 1614, in full_dispatch_request
    rv = self.handle_user_exception(e)
  File "c:\python36\lib\site-packages\flask\app.py", line 1517, in handle_user_exception
    reraise(exc_type, exc_value, tb)
  File "c:\python36\lib\site-packages\flask\_compat.py", line 33, in reraise
    raise value
  File "c:\python36\lib\site-packages\flask\app.py", line 1612, in full_dispatch_request
    rv = self.dispatch_request()
  File "c:\python36\lib\site-packages\flask\app.py", line 1598, in dispatch_request
    return self.view_functions[rule.endpoint](**req.view_args)
  File "C:\Users\Adam\desktop\City Tech Proj\app\routes.py", line 280, in editCourseForm
    prereq_course = Courses.query.filter_by(id=prereq_course_id).one()
  File "c:\python36\lib\site-packages\sqlalchemy\orm\query.py", line 2843, in one
    raise orm_exc.NoResultFound("No row was found for one()")
sqlalchemy.orm.exc.NoResultFound: No row was found for one()
2019-03-31 20:53:44,547 INFO: CreditTracker startup [in C:\Users\Adam\desktop\City Tech Proj\app\__init__.py:37]
2019-03-31 20:54:15,441 ERROR: Exception on /courses/edit/2 [POST] [in c:\python36\lib\site-packages\flask\app.py:1560]
Traceback (most recent call last):
  File "c:\python36\lib\site-packages\flask\app.py", line 1982, in wsgi_app
    response = self.full_dispatch_request()
  File "c:\python36\lib\site-packages\flask\app.py", line 1614, in full_dispatch_request
    rv = self.handle_user_exception(e)
  File "c:\python36\lib\site-packages\flask\app.py", line 1517, in handle_user_exception
    reraise(exc_type, exc_value, tb)
  File "c:\python36\lib\site-packages\flask\_compat.py", line 33, in reraise
    raise value
  File "c:\python36\lib\site-packages\flask\app.py", line 1612, in full_dispatch_request
    rv = self.dispatch_request()
  File "c:\python36\lib\site-packages\flask\app.py", line 1598, in dispatch_request
    return self.view_functions[rule.endpoint](**req.view_args)
  File "C:\Users\Adam\desktop\City Tech Proj\app\routes.py", line 297, in editCourseForm
    coreq_course = Courses.query.filter_by(id=coreq_course_id).one()
  File "c:\python36\lib\site-packages\sqlalchemy\orm\query.py", line 2843, in one
    raise orm_exc.NoResultFound("No row was found for one()")
sqlalchemy.orm.exc.NoResultFound: No row was found for one()
2019-03-31 20:56:08,497 INFO: CreditTracker startup [in C:\Users\Adam\desktop\City Tech Proj\app\__init__.py:37]
2019-03-31 20:56:33,614 ERROR: Exception on /courses/edit/2 [POST] [in c:\python36\lib\site-packages\flask\app.py:1560]
Traceback (most recent call last):
  File "c:\python36\lib\site-packages\flask\app.py", line 1982, in wsgi_app
    response = self.full_dispatch_request()
  File "c:\python36\lib\site-packages\flask\app.py", line 1614, in full_dispatch_request
    rv = self.handle_user_exception(e)
  File "c:\python36\lib\site-packages\flask\app.py", line 1517, in handle_user_exception
    reraise(exc_type, exc_value, tb)
  File "c:\python36\lib\site-packages\flask\_compat.py", line 33, in reraise
    raise value
  File "c:\python36\lib\site-packages\flask\app.py", line 1612, in full_dispatch_request
    rv = self.dispatch_request()
  File "c:\python36\lib\site-packages\flask\app.py", line 1598, in dispatch_request
    return self.view_functions[rule.endpoint](**req.view_args)
  File "C:\Users\Adam\desktop\City Tech Proj\app\routes.py", line 297, in editCourseForm
    coreq_course = Courses.query.filter_by(id=coreq_course_id).one()
  File "c:\python36\lib\site-packages\sqlalchemy\orm\query.py", line 2843, in one
    raise orm_exc.NoResultFound("No row was found for one()")
sqlalchemy.orm.exc.NoResultFound: No row was found for one()
2019-03-31 21:09:22,568 INFO: CreditTracker startup [in C:\Users\Adam\desktop\City Tech Proj\app\__init__.py:37]
2019-03-31 21:09:44,367 ERROR: Exception on /courses/edit/2 [POST] [in c:\python36\lib\site-packages\flask\app.py:1560]
Traceback (most recent call last):
  File "c:\python36\lib\site-packages\flask\app.py", line 1982, in wsgi_app
    response = self.full_dispatch_request()
  File "c:\python36\lib\site-packages\flask\app.py", line 1614, in full_dispatch_request
    rv = self.handle_user_exception(e)
  File "c:\python36\lib\site-packages\flask\app.py", line 1517, in handle_user_exception
    reraise(exc_type, exc_value, tb)
  File "c:\python36\lib\site-packages\flask\_compat.py", line 33, in reraise
    raise value
  File "c:\python36\lib\site-packages\flask\app.py", line 1612, in full_dispatch_request
    rv = self.dispatch_request()
  File "c:\python36\lib\site-packages\flask\app.py", line 1598, in dispatch_request
    return self.view_functions[rule.endpoint](**req.view_args)
  File "C:\Users\Adam\desktop\City Tech Proj\app\routes.py", line 297, in editCourseForm
    coreq_course = Courses.query.filter_by(id=coreq_course_id).one()
  File "c:\python36\lib\site-packages\sqlalchemy\orm\query.py", line 2843, in one
    raise orm_exc.NoResultFound("No row was found for one()")
sqlalchemy.orm.exc.NoResultFound: No row was found for one()
2019-03-31 21:10:08,788 INFO: CreditTracker startup [in C:\Users\Adam\desktop\City Tech Proj\app\__init__.py:37]
2019-03-31 21:17:02,776 INFO: CreditTracker startup [in C:\Users\Adam\desktop\City Tech Proj\app\__init__.py:37]
